<?xml version="1.0" ?>
<!-- =================================================================================== -->
<!-- |    This document was autogenerated by xacro from panda_arm_hand.urdf.xacro      | -->
<!-- |    EDITING THIS FILE BY HAND IS NOT RECOMMENDED                                 | -->
<!-- =================================================================================== -->
<robot name="panda" xmlns:xacro="http://www.ros.org/wiki/xacro">
  <link name="panda_link0">
  	<inertial>
      <origin rpy="0 0 0" xyz="0 0 0.05"/>
       <mass value="2.9"/>
       <inertia ixx="0.1" ixy="0" ixz="0" iyy="0.1" iyz="0" izz="0.1"/>
    </inertial>
    <visual>
      <geometry>
        <mesh filename="package://meshes/collision/link0.obj"/>
      </geometry>
      <material name="panda_white">
    		<color rgba="1. 1. 1. 1."/>
  		</material>
    </visual>
    <collision>
      <geometry>
        <mesh filename="package://meshes/collision/link0.obj"/>
      </geometry>
      <material name="panda_white"/>
    </collision>
  </link>
  <link name="panda_link1">
  	<inertial>
      <origin rpy="0 0 0" xyz="0 -0.04 -0.05"/>
       <mass value="2.7"/>
       <inertia ixx="0.1" ixy="0" ixz="0" iyy="0.1" iyz="0" izz="0.1"/>
    </inertial>
    <visual>
      <geometry>
        <mesh filename="package://meshes/visual/link1.obj"/>
      </geometry>
      <material name="panda_white"/>
    </visual>
    <collision>
      <geometry>
        <mesh filename="package://meshes/collision/link1.obj"/>
      </geometry>
      <material name="panda_white"/>
    </collision>
  </link>
  <joint name="panda_joint1" type="revolute">
    <safety_controller k_position="100.0" k_velocity="40.0" soft_lower_limit="-2.8973" soft_upper_limit="2.8973"/>
    <origin rpy="0 0 0" xyz="0 0 0.333"/>
    <parent link="panda_link0"/>
    <child link="panda_link1"/>
    <axis xyz="0 0 1"/>
    <limit effort="87" lower="-2.9671" upper="2.9671" velocity="2.1750"/>
  </joint>
  <link name="panda_link2">
  	<inertial>
      <origin rpy="0 0 0" xyz="0 -0.04 0.06"/>
       <mass value="2.73"/>
       <inertia ixx="0.1" ixy="0" ixz="0" iyy="0.1" iyz="0" izz="0.1"/>
    </inertial>
    <visual>
      <geometry>
        <mesh filename="package://meshes/visual/link2.obj"/>
      </geometry>
      <material name="panda_white"/>
    </visual>
    <collision>
      <geometry>
        <mesh filename="package://meshes/collision/link2.obj"/>
      </geometry>
      <material name="panda_white"/>
    </collision>
  </link>
  <joint name="panda_joint2" type="revolute">
    <safety_controller k_position="100.0" k_velocity="40.0" soft_lower_limit="-1.7628" soft_upper_limit="1.7628"/>
    <origin rpy="-1.57079632679 0 0" xyz="0 0 0"/>
    <parent link="panda_link1"/>
    <child link="panda_link2"/>
    <axis xyz="0 0 1"/>
    <limit effort="87" lower="-1.8326" upper="1.8326" velocity="2.1750"/>
  </joint>
  <link name="panda_link3">
	  <inertial>
      <origin rpy="0 0 0" xyz="0.01 0.01 -0.05"/>
       <mass value="2.04"/>
       <inertia ixx="0.1" ixy="0" ixz="0" iyy="0.1" iyz="0" izz="0.1"/>
    </inertial>
    <visual>
      <geometry>
        <mesh filename="package://meshes/visual/link3.obj"/>
      </geometry>
      <material name="panda_red">
    		<color rgba="1. 1. 1. 1."/>
  		</material>
    </visual>
    <collision>
      <geometry>
        <mesh filename="package://meshes/collision/link3.obj"/>
      </geometry>
    </collision>
  </link>
  <joint name="panda_joint3" type="revolute">
    <safety_controller k_position="100.0" k_velocity="40.0" soft_lower_limit="-2.8973" soft_upper_limit="2.8973"/>
    <origin rpy="1.57079632679 0 0" xyz="0 -0.316 0"/>
    <parent link="panda_link2"/>
    <child link="panda_link3"/>
    <axis xyz="0 0 1"/>
    <limit effort="87" lower="-2.9671" upper="2.9671" velocity="2.1750"/>
  </joint>
  <link name="panda_link4">
  	<inertial>
      <origin rpy="0 0 0" xyz="-0.03 0.03 0.02"/>
       <mass value="2.08"/>
       <inertia ixx="0.1" ixy="0" ixz="0" iyy="0.1" iyz="0" izz="0.1"/>
    </inertial>
    <visual>
      <geometry>
        <mesh filename="package://meshes/visual/link4.obj"/>
      </geometry>
      <material name="panda_white"/>
    </visual>
    <collision>
      <geometry>
        <mesh filename="package://meshes/collision/link4.obj"/>
      </geometry>
      <material name="panda_white"/>
    </collision>
  </link>
  <joint name="panda_joint4" type="revolute">
    <safety_controller k_position="100.0" k_velocity="40.0" soft_lower_limit="-3.0718" soft_upper_limit="-0.0698"/>
    <origin rpy="1.57079632679 0 0" xyz="0.0825 0 0"/>
    <parent link="panda_link3"/>
    <child link="panda_link4"/>
    <axis xyz="0 0 1"/>
    <limit effort="87" lower="-3.1416" upper="0.0" velocity="2.1750"/>
  </joint>
  <link name="panda_link5">
  	<inertial>
      <origin rpy="0 0 0" xyz="0 0.04 -0.12"/>
       <mass value="3"/>
       <inertia ixx="0.1" ixy="0" ixz="0" iyy="0.1" iyz="0" izz="0.1"/>
    </inertial>
    <visual>
      <geometry>
        <mesh filename="package://meshes/visual/link5.obj"/>
      </geometry>
      <material name="panda_white"/>
    </visual>
    <collision>
      <geometry>
        <mesh filename="package://meshes/collision/link5.obj"/>
      </geometry>
      <material name="panda_white"/>
    </collision>
  </link>
  <joint name="panda_joint5" type="revolute">
    <safety_controller k_position="100.0" k_velocity="40.0" soft_lower_limit="-2.8973" soft_upper_limit="2.8973"/>
    <origin rpy="-1.57079632679 0 0" xyz="-0.0825 0.384 0"/>
    <parent link="panda_link4"/>
    <child link="panda_link5"/>
    <axis xyz="0 0 1"/>
    <limit effort="12" lower="-2.9671" upper="2.9671" velocity="2.6100"/>
  </joint>
  <link name="panda_link6">
  	<inertial>
      <origin rpy="0 0 0" xyz="0.04 0 0"/>
       <mass value="1.3"/>
       <inertia ixx="0.1" ixy="0" ixz="0" iyy="0.1" iyz="0" izz="0.1"/>
    </inertial>
    <visual>
      <geometry>
        <mesh filename="package://meshes/visual/link6.obj"/>
      </geometry>
      <material name="panda_white"/>
    </visual>
    <collision>
      <geometry>
        <mesh filename="package://meshes/collision/link6.obj"/>
      </geometry>
      <material name="panda_white"/>
    </collision>
  </link>
  <joint name="panda_joint6" type="revolute">
    <safety_controller k_position="100.0" k_velocity="40.0" soft_lower_limit="-0.0175" soft_upper_limit="3.7525"/>
    <origin rpy="1.57079632679 0 0" xyz="0 0 0"/>
    <parent link="panda_link5"/>
    <child link="panda_link6"/>
    <axis xyz="0 0 1"/>
    <limit effort="12" lower="-0.0873" upper="3.8223" velocity="2.6100"/>
  </joint>
  <link name="panda_link7">
  	<inertial>
      <origin rpy="0 0 0" xyz="0 0 0.08"/>
       <mass value=".2"/>
       <inertia ixx="0.1" ixy="0" ixz="0" iyy="0.1" iyz="0" izz="0.1"/>
    </inertial>
    <visual>
      <geometry>
        <mesh filename="package://meshes/collision/link7.obj"/>
      </geometry>
      <material name="panda_white"/>
    </visual>
    <collision>
      <geometry>
        <mesh filename="package://meshes/collision/link7.obj"/>
      </geometry>
      <material name="panda_white"/>
    </collision>
  </link>
  <joint name="panda_joint7" type="revolute">
    <safety_controller k_position="100.0" k_velocity="40.0" soft_lower_limit="-2.8973" soft_upper_limit="2.8973"/>
    <origin rpy="1.57079632679 0 0" xyz="0.088 0 0"/>
    <parent link="panda_link6"/>
    <child link="panda_link7"/>
    <axis xyz="0 0 1"/>
    <limit effort="12" lower="-2.9671" upper="2.9671" velocity="2.6100"/>
  </joint>
  <link name="panda_link8">
  	 <inertial>
      <origin rpy="0 0 0" xyz="0 0 0"/>
       <mass value="0.0"/>
       <inertia ixx="0.1" ixy="0" ixz="0" iyy="0.1" iyz="0" izz="0.1"/>
    </inertial>
  </link>
  <joint name="panda_joint8" type="fixed">
    <origin rpy="0 0 0" xyz="0 0 0.107"/>
    <parent link="panda_link7"/>
    <child link="panda_link8"/>
    <axis xyz="0 0 0"/>
  </joint>
  
  
  
  
  
<!-- =================================================================================== -->
<!-- =================================================================================== -->
<!-- =================================================================================== -->
<!-- =================================================================================== -->
<!-- Reflex hand starts here -->


  <joint name="connecting_joint" type="fixed">
    <origin rpy="0 0 0" xyz="0 0 0"/>
    <parent link="panda_link8"/>
    <child link="shell"/>
    <axis xyz="0 0 0"/>
  </joint>



<!-- Reflex hand starts here -->
<!-- =================================================================================== -->
<!-- =================================================================================== -->
<!-- =================================================================================== -->



<link name="shell">
    <visual>
      <origin rpy="0 0 0" xyz="0 0 0"/>
      <geometry>
        <mesh filename="package://meshes/base_link.STL"/>
      </geometry>
      <material name="black"/>
    </visual>
    <inertial>
      <origin rpy="0 0 0" xyz="0 0 0"/>
      <mass value="0.74"/>
      <inertia ixx="0.0016512483333333333" ixy="0.0" ixz="0.0" iyy="0.0014092066666666668" iyz="0.0" izz="0.0007792816666666667"/>
    </inertial>
    <collision>
      <origin rpy="0 0 0" xyz="0 0 0"/>
      <geometry>
        <mesh filename="package://meshes/base_link_coll.STL"/>
      </geometry>
    </collision>
  </link>
  <link name="pad">
    <visual>
      <origin rpy="0 0 0" xyz="0 0 0"/>
      <geometry>
        <mesh filename="package://meshes/pad.STL"/>
      </geometry>
      <material name="dark_grey">
        <color rgba="0.2 0.2 0.2 1"/>
      </material>
    </visual>
    <inertial>
      <origin rpy="0 0 0" xyz="0 0 0"/>
      <mass value="0.1"/>
      <inertia ixx="0.0002231416666666667" ixy="0.0" ixz="0.0" iyy="0.00019043333333333337" iyz="0.0" izz="0.00010530833333333334"/>
    </inertial>
    <collision>
      <origin rpy="0 0 0" xyz="0 0 0"/>
      <geometry>
        <mesh filename="package://meshes/pad_coll.STL"/>
      </geometry>
    </collision>
  </link>
  <joint name="shell_to_pad" type="fixed">
    <origin rpy="1.570796326795 0 -1.570796326795" xyz="0.02 0 0.063"/>
    <parent link="shell"/>
    <child link="pad"/>
    <axis xyz="0 0 0"/>
  </joint>
  <joint name="preshape_1" type="revolute">
    <parent link="shell"/>
    <child link="swivel_1"/>
    <limit effort="15" lower="0.0" upper="1.570796326795" velocity="7"/>
    <origin rpy="0 0 0" xyz="0.0503973683071414 -0.026 0.063"/>
    <axis xyz="0 0 -1"/>
  </joint>
  <link name="swivel_1">
    <visual>
      <origin rpy="0 0 0" xyz="0 0 0"/>
      <geometry>
        <mesh filename="package://meshes/swivel_1.STL"/>
      </geometry>
      <material name="black"/>
    </visual>
    <inertial>
      <origin rpy="0 0 0" xyz="0 0 0"/>
      <mass value="0.01"/>
      <inertia ixx="1.6033333333333332e-06" ixy="0.0" ixz="0.0" iyy="1.153333333333333e-06" iyz="0.0" izz="1.2566666666666664e-06"/>
    </inertial>
    <collision>
      <origin rpy="0 0 0" xyz="0 0 0"/>
      <geometry>
        <mesh filename="package://meshes/swivel_1_coll.STL"/>
      </geometry>
    </collision>
  </link>
  <joint name="proximal_joint_1" type="revolute">
    <child link="proximal_1"/>
    <axis xyz="0 -1 0"/>
    <limit effort="15" lower="0.0" upper="3.14159265359" velocity="7"/>
    <origin rpy="0 0.28 0" xyz="0.01 0 0.0186"/>
    <parent link="swivel_1"/>
  </joint>
  <link name="proximal_1">
    <visual>
      <origin rpy="3.14159265359 0 0" xyz="-0.011 0.007 0.011"/>
      <geometry>
        <mesh filename="package://meshes/proximal.STL"/>
      </geometry>
      <material name="black"/>
    </visual>
    <inertial>
      <origin rpy="3.14159265359 0 0" xyz="-0.011 0.007 0.011"/>
      <mass value="0.01"/>
      <inertia ixx="2.295083333333333e-05" ixy="0.0" ixz="0.0" iyy="4.534166666666666e-06" iyz="0.0" izz="1.908333333333333e-05"/>
    </inertial>
    <collision>
      <origin rpy="3.14159265359 0 0" xyz="-0.011 0.007 0.011"/>
      <geometry>
        <mesh filename="package://meshes/proximal_coll.STL"/>
      </geometry>
    </collision>
  </link>
  <joint name="proximal_1_to_pad" type="fixed">
    <origin rpy="1.570796326795 0 -1.570796326795" xyz="0 0 0"/>
    <parent link="proximal_1"/>
    <child link="proximal_1_pad"/>
  </joint>
  <link name="proximal_1_pad">
    <visual>
      <origin rpy="1.570796326795 1.570796326795 0" xyz="-0.008 0.014 -0.002"/>
      <geometry>
        <mesh filename="package://meshes/proximal_pad.STL"/>
      </geometry>
      <material name="dark_grey">
        <color rgba="0.2 0.2 0.2 1"/>
      </material>
    </visual>
    <inertial>
      <origin rpy="1.570796326795 1.570796326795 0" xyz="-0.008 0.014 -0.002"/>
      <mass value="0.01"/>
      <inertia ixx="2.295083333333333e-05" ixy="0.0" ixz="0.0" iyy="4.2216666666666655e-06" iyz="0.0" izz="1.8770833333333333e-05"/>
    </inertial>
    <collision>
      <origin rpy="1.570796326795 1.570796326795 0" xyz="-0.008 0.014 -0.002"/>
      <geometry>
        <mesh filename="package://meshes/proximal_pad_coll.STL"/>
      </geometry>
    </collision>
  </link>
  <joint name="proximal_1_to_flex" type="fixed">
    <origin rpy="0 0 0" xyz="0.07 0 0.004"/>
    <parent link="proximal_1"/>
    <child link="finger_1_flex_link"/>
  </joint>
  <link name="finger_1_flex_link">
    <visual>
      <origin rpy="0 0 0" xyz="0.0005 0 -0.003"/>
      <geometry>
        <box size="0.017 0.014 0.0065"/>
      </geometry>
      <material name="gold">
        <color rgba="0.996078431372549 0.8470588235294118 0.36470588235294116 1"/>
      </material>
    </visual>
    <inertial>
      <origin rpy="0 0 0" xyz="0 0 0"/>
      <mass value="0.01"/>
      <inertia ixx="3.5083333333333334e-07" ixy="0.0" ixz="0.0" iyy="2.0833333333333333e-07" iyz="0.0" izz="1.841666666666667e-07"/>
    </inertial>
    <collision>
      <origin rpy="0 0 0" xyz="0 0 0"/>
      <geometry>
        <box size="0.01 0.01 0.01"/>
      </geometry>
    </collision>
  </link>
  <joint name="flex_to_distal_1" type="fixed">
    <origin rpy="0 0 0" xyz="0 0 0"/>
    <parent link="finger_1_flex_link"/>
    <child link="distal_1"/>
  </joint>
  <link name="distal_1">
    <visual>
      <origin rpy="3.14159265359 0 0" xyz="-0.077 0.007 0.007"/>
      <geometry>
        <mesh filename="package://meshes/distal.STL"/>
      </geometry>
      <material name="black"/>
    </visual>
    <inertial>
      <origin rpy="3.1459 0 0" xyz="-0.077 0.007 0.007"/>
      <mass value="0.01"/>
      <inertia ixx="2.00175e-05" ixy="0.0" ixz="0.0" iyy="1.5083333333333332e-06" iyz="0.0" izz="1.899083333333333e-05"/>
    </inertial>
    <collision>
      <origin rpy="3.14159265359 0 0" xyz="-0.077 0.007 0.007"/>
      <geometry>
        <mesh filename="package://meshes/distal_coll.STL"/>
      </geometry>
    </collision>
  </link>
  <joint name="distal_1_to_pad" type="fixed">
    <origin rpy="1.570796326795 0 -1.570796326795" xyz="-0.01 0 0.001"/>
    <parent link="distal_1"/>
    <child link="distal_1_pad"/>
  </joint>
  <link name="distal_1_pad">
    <visual>
      <origin rpy="1.570796326795 1.570796326795 0" xyz="-0.00825 0.009 0.057"/>
      <geometry>
        <mesh filename="package://meshes/distal_pad.STL"/>
      </geometry>
      <material name="dark_grey">
        <color rgba="0.2 0.2 0.2 1"/>
      </material>
    </visual>
    <inertial>
      <origin rpy="1.570796326795 1.570796326795 0" xyz="-0.00825 0.009 0.057"/>
      <mass value="0.01"/>
      <inertia ixx="2.00175e-05" ixy="0.0" ixz="0.0" iyy="1.2883333333333332e-06" iyz="0.0" izz="1.8770833333333333e-05"/>
    </inertial>
    <collision>
      <origin rpy="1.570796326795 1.570796326795 0" xyz="-0.00825 0.009 0.057"/>
      <geometry>
        <mesh filename="package://meshes/distal_pad_coll.STL"/>
      </geometry>
    </collision>
  </link>
  <joint name="preshape_2" type="revolute">
    <parent link="shell"/>
    <child link="swivel_2"/>
    <limit effort="15" lower="0.0" upper="1.570796326795" velocity="7"/>
    <origin rpy="0 0 0" xyz="0.0503973683071413 0.026 0.063"/>
    <axis xyz="0 0 1"/>
  </joint>
  <link name="swivel_2">
    <visual>
      <origin rpy="0 0 0" xyz="0 0 0"/>
      <geometry>
        <mesh filename="package://meshes/swivel_2.STL"/>
      </geometry>
      <material name="black"/>
    </visual>
    <inertial>
      <origin rpy="0 0 0" xyz="0 0 0"/>
      <mass value="0.01"/>
      <inertia ixx="1.6033333333333332e-06" ixy="0.0" ixz="0.0" iyy="1.153333333333333e-06" iyz="0.0" izz="1.2566666666666664e-06"/>
    </inertial>
    <collision>
      <origin rpy="0 0 0" xyz="0 0 0"/>
      <geometry>
        <mesh filename="package://meshes/swivel_2_coll.STL"/>
      </geometry>
    </collision>
  </link>
  <joint name="proximal_joint_2" type="revolute">
    <child link="proximal_2"/>
    <axis xyz="0 -1 0"/>
    <limit effort="15" lower="0.0" upper="3.14159265359" velocity="7"/>
    <origin rpy="0 0.28 0" xyz="0.01 0 0.0186"/>
    <parent link="swivel_2"/>
  </joint>
  <link name="proximal_2">
    <visual>
      <origin rpy="3.14159265359 0 0" xyz="-0.011 0.007 0.011"/>
      <geometry>
        <mesh filename="package://meshes/proximal.STL"/>
      </geometry>
      <material name="black"/>
    </visual>
    <inertial>
      <origin rpy="3.14159265359 0 0" xyz="-0.011 0.007 0.011"/>
      <mass value="0.01"/>
      <inertia ixx="2.295083333333333e-05" ixy="0.0" ixz="0.0" iyy="4.534166666666666e-06" iyz="0.0" izz="1.908333333333333e-05"/>
    </inertial>
    <collision>
      <origin rpy="3.14159265359 0 0" xyz="-0.011 0.007 0.011"/>
      <geometry>
        <mesh filename="package://meshes/proximal_coll.STL"/>
      </geometry>
    </collision>
  </link>
  <joint name="proximal_2_to_pad" type="fixed">
    <origin rpy="1.570796326795 0 -1.570796326795" xyz="0 0 0"/>
    <parent link="proximal_2"/>
    <child link="proximal_2_pad"/>
  </joint>
  <link name="proximal_2_pad">
    <visual>
      <origin rpy="1.570796326795 1.570796326795 0" xyz="-0.008 0.014 -0.002"/>
      <geometry>
        <mesh filename="package://meshes/proximal_pad.STL"/>
      </geometry>
      <material name="dark_grey">
        <color rgba="0.2 0.2 0.2 1"/>
      </material>
    </visual>
    <inertial>
      <origin rpy="1.570796326795 1.570796326795 0" xyz="-0.008 0.014 -0.002"/>
      <mass value="0.01"/>
      <inertia ixx="2.295083333333333e-05" ixy="0.0" ixz="0.0" iyy="4.2216666666666655e-06" iyz="0.0" izz="1.8770833333333333e-05"/>
    </inertial>
    <collision>
      <origin rpy="1.570796326795 1.570796326795 0" xyz="-0.008 0.014 -0.002"/>
      <geometry>
        <mesh filename="package://meshes/proximal_pad_coll.STL"/>
      </geometry>
    </collision>
  </link>
  <joint name="proximal_2_to_flex" type="fixed">
    <origin rpy="0 0 0" xyz="0.07 0 0.004"/>
    <parent link="proximal_2"/>
    <child link="finger_2_flex_link"/>
  </joint>
  <link name="finger_2_flex_link">
    <visual>
      <origin rpy="0 0 0" xyz="0.0005 0 -0.003"/>
      <geometry>
        <box size="0.017 0.014 0.0065"/>
      </geometry>
      <material name="gold">
        <color rgba="0.996078431372549 0.8470588235294118 0.36470588235294116 1"/>
      </material>
    </visual>
    <inertial>
      <origin rpy="0 0 0" xyz="0 0 0"/>
      <mass value="0.01"/>
      <inertia ixx="3.5083333333333334e-07" ixy="0.0" ixz="0.0" iyy="2.0833333333333333e-07" iyz="0.0" izz="1.841666666666667e-07"/>
    </inertial>
    <collision>
      <origin rpy="0 0 0" xyz="0 0 0"/>
      <geometry>
        <box size="0.01 0.01 0.01"/>
      </geometry>
    </collision>
  </link>
  <joint name="flex_to_distal_2" type="fixed">
    <origin rpy="0 0 0" xyz="0 0 0"/>
    <parent link="finger_2_flex_link"/>
    <child link="distal_2"/>
  </joint>
  <link name="distal_2">
    <visual>
      <origin rpy="3.14159265359 0 0" xyz="-0.077 0.007 0.007"/>
      <geometry>
        <mesh filename="package://meshes/distal.STL"/>
      </geometry>
      <material name="black"/>
    </visual>
    <inertial>
      <origin rpy="3.1459 0 0" xyz="-0.077 0.007 0.007"/>
      <mass value="0.01"/>
      <inertia ixx="2.00175e-05" ixy="0.0" ixz="0.0" iyy="1.5083333333333332e-06" iyz="0.0" izz="1.899083333333333e-05"/>
    </inertial>
    <collision>
      <origin rpy="3.14159265359 0 0" xyz="-0.077 0.007 0.007"/>
      <geometry>
        <mesh filename="package://meshes/distal_coll.STL"/>
      </geometry>
    </collision>
  </link>
  <joint name="distal_2_to_pad" type="fixed">
    <origin rpy="1.570796326795 0 -1.570796326795" xyz="-0.01 0 0.001"/>
    <parent link="distal_2"/>
    <child link="distal_2_pad"/>
  </joint>
  <link name="distal_2_pad">
    <visual>
      <origin rpy="1.570796326795 1.570796326795 0" xyz="-0.00825 0.009 0.057"/>
      <geometry>
        <mesh filename="package://meshes/distal_pad.STL"/>
      </geometry>
      <material name="dark_grey">
        <color rgba="0.2 0.2 0.2 1"/>
      </material>
    </visual>
    <inertial>
      <origin rpy="1.570796326795 1.570796326795 0" xyz="-0.00825 0.009 0.057"/>
      <mass value="0.01"/>
      <inertia ixx="2.00175e-05" ixy="0.0" ixz="0.0" iyy="1.2883333333333332e-06" iyz="0.0" izz="1.8770833333333333e-05"/>
    </inertial>
    <collision>
      <origin rpy="1.570796326795 1.570796326795 0" xyz="-0.00825 0.009 0.057"/>
      <geometry>
        <mesh filename="package://meshes/distal_pad_coll.STL"/>
      </geometry>
    </collision>
  </link>
  <joint name="proximal_joint_3" type="revolute">
    <child link="proximal_3"/>
    <axis xyz="0 -1 0"/>
    <limit effort="15" lower="0.0" upper="3.14159265359" velocity="7"/>
    <origin rpy="0 0.28 3.14159265359" xyz="-0.03 0 0.0816"/>
    <parent link="shell"/>
  </joint>
  <link name="proximal_3">
    <visual>
      <origin rpy="3.14159265359 0 0" xyz="-0.011 0.007 0.011"/>
      <geometry>
        <mesh filename="package://meshes/proximal.STL"/>
      </geometry>
      <material name="black"/>
    </visual>
    <inertial>
      <origin rpy="3.14159265359 0 0" xyz="-0.011 0.007 0.011"/>
      <mass value="0.01"/>
      <inertia ixx="2.295083333333333e-05" ixy="0.0" ixz="0.0" iyy="4.534166666666666e-06" iyz="0.0" izz="1.908333333333333e-05"/>
    </inertial>
    <collision>
      <origin rpy="3.14159265359 0 0" xyz="-0.011 0.007 0.011"/>
      <geometry>
        <mesh filename="package://meshes/proximal_coll.STL"/>
      </geometry>
    </collision>
  </link>
  <joint name="proximal_3_to_pad" type="fixed">
    <origin rpy="1.570796326795 0 -1.570796326795" xyz="0 0 0"/>
    <parent link="proximal_3"/>
    <child link="proximal_3_pad"/>
  </joint>
  <link name="proximal_3_pad">
    <visual>
      <origin rpy="1.570796326795 1.570796326795 0" xyz="-0.008 0.014 -0.002"/>
      <geometry>
        <mesh filename="package://meshes/proximal_pad.STL"/>
      </geometry>
      <material name="dark_grey">
        <color rgba="0.2 0.2 0.2 1"/>
      </material>
    </visual>
    <inertial>
      <origin rpy="1.570796326795 1.570796326795 0" xyz="-0.008 0.014 -0.002"/>
      <mass value="0.01"/>
      <inertia ixx="2.295083333333333e-05" ixy="0.0" ixz="0.0" iyy="4.2216666666666655e-06" iyz="0.0" izz="1.8770833333333333e-05"/>
    </inertial>
    <collision>
      <origin rpy="1.570796326795 1.570796326795 0" xyz="-0.008 0.014 -0.002"/>
      <geometry>
        <mesh filename="package://meshes/proximal_pad_coll.STL"/>
      </geometry>
    </collision>
  </link>
  <joint name="proximal_3_to_flex" type="fixed">
    <origin rpy="0 0 0" xyz="0.07 0 0.004"/>
    <parent link="proximal_3"/>
    <child link="finger_3_flex_link"/>
  </joint>
  <link name="finger_3_flex_link">
    <visual>
      <origin rpy="0 0 0" xyz="0.0005 0 -0.003"/>
      <geometry>
        <box size="0.017 0.014 0.0065"/>
      </geometry>
      <material name="gold">
        <color rgba="0.996078431372549 0.8470588235294118 0.36470588235294116 1"/>
      </material>
    </visual>
    <inertial>
      <origin rpy="0 0 0" xyz="0 0 0"/>
      <mass value="0.01"/>
      <inertia ixx="3.5083333333333334e-07" ixy="0.0" ixz="0.0" iyy="2.0833333333333333e-07" iyz="0.0" izz="1.841666666666667e-07"/>
    </inertial>
    <collision>
      <origin rpy="0 0 0" xyz="0 0 0"/>
      <geometry>
        <box size="0.01 0.01 0.01"/>
      </geometry>
    </collision>
  </link>
  <joint name="flex_to_distal_3" type="fixed">
    <origin rpy="0 0 0" xyz="0 0 0"/>
    <parent link="finger_3_flex_link"/>
    <child link="distal_3"/>
  </joint>
  <link name="distal_3">
    <visual>
      <origin rpy="3.14159265359 0 0" xyz="-0.077 0.007 0.007"/>
      <geometry>
        <mesh filename="package://meshes/distal.STL"/>
      </geometry>
      <material name="black"/>
    </visual>
    <inertial>
      <origin rpy="3.1459 0 0" xyz="-0.077 0.007 0.007"/>
      <mass value="0.01"/>
      <inertia ixx="2.00175e-05" ixy="0.0" ixz="0.0" iyy="1.5083333333333332e-06" iyz="0.0" izz="1.899083333333333e-05"/>
    </inertial>
    <collision>
      <origin rpy="3.14159265359 0 0" xyz="-0.077 0.007 0.007"/>
      <geometry>
        <mesh filename="package://meshes/distal_coll.STL"/>
      </geometry>
    </collision>
  </link>
  <joint name="distal_3_to_pad" type="fixed">
    <origin rpy="1.570796326795 0 -1.570796326795" xyz="-0.01 0 0.001"/>
    <parent link="distal_3"/>
    <child link="distal_3_pad"/>
  </joint>
  <link name="distal_3_pad">
    <visual>
      <origin rpy="1.570796326795 1.570796326795 0" xyz="-0.00825 0.009 0.057"/>
      <geometry>
        <mesh filename="package://meshes/distal_pad.STL"/>
      </geometry>
      <material name="dark_grey">
        <color rgba="0.2 0.2 0.2 1"/>
      </material>
    </visual>
    <inertial>
      <origin rpy="1.570796326795 1.570796326795 0" xyz="-0.00825 0.009 0.057"/>
      <mass value="0.01"/>
      <inertia ixx="2.00175e-05" ixy="0.0" ixz="0.0" iyy="1.2883333333333332e-06" iyz="0.0" izz="1.8770833333333333e-05"/>
    </inertial>
    <collision>
      <origin rpy="1.570796326795 1.570796326795 0" xyz="-0.00825 0.009 0.057"/>
      <geometry>
        <mesh filename="package://meshes/distal_pad_coll.STL"/>
      </geometry>
    </collision>
  </link>
  
  
  
  
  
  
  
  
  
  
  
  
  
  
  
  
  
  
  
  
  
  
  
  
  
  
  
  
  
  
  
  
  
  
  
  

</robot> 
